Workbook

Sheet Лист1
A1: Оборудование производства
A2: № п/п | B2: Наименование оборудования | C2: Цех | D2: Подразделение | E2: Операция 1 | F2: Операция 2 | G2: Операция 3
A3: 1 | B3: Установка дробеметная с рольгангами 2006 г.в, инв.№000489903/0000277 | C3: ДорИнвест | D3: Отдел сварки и сборки Серийных изделий | E3: Очистка дробеметная
A4: 2 | B4: Камера пескоструйная; Установка абразивоструйная напорного типа DSG-200 (200л, 8,3bar) | C4: ДорИнвест | D4: Отдел сварки и сборки Серийных изделий | E4: Очистка пескоструйная
A5: 3 | B5: Гидростанция для проверки | C5: ДорИнвест | D5: Отдел сварки и сборки Габаритных изделий | E5: Сборка/Разборка | F5: Испытание
A6: 4 | B6: Маленький сверлильный станок ELITECH | C6: ДорИнвест | D6: Отдел сварки и сборки Габаритных изделий | E6: Слесарная | F6: Сверлильная
A7: 5 | B7: Аппарат сварочный HUGONG | C7: ДорИнвест | D7: Отдел сварки и сборки Серийных изделий | E7: Сварка полуавтоматическая | F7: Прихватка
A8: 6 | B8: Аппарат сварочный ESAB Aristo Mig 5000iw зав.№941-109-0577, Польша, инв. №000769849 | C8: ДорИнвест | D8: Отдел сварки и сборки Серийных изделий | E8: Сварка полуавтоматическая | F8: Прихватка
A9: 7 | B9: Аппарат сварочный ESAB Warrior Feed 304w зав.№512-903-6840, 2019 г.в., инв.№000577318 | C9: ДорИнвест | D9: Отдел сварки и сборки Серийных изделий | E9: Сварка полуавтоматическая | F9: Прихватка
A10: 8 | B10: Сварочный позиционер ESSAB 750 AHMA, зав.№A9596, инв.№000346381 | C10: ДорИнвест | D10: Отдел сварки и сборки Серийных изделий | E10: Сварка полуавтоматическая | F10: Прихватка
A11: 9 | B11: Аппарат сварочный ESAB Aristo Mig 5000iw зав.№551-805-2287, 2013 г.в., инв.№00-000290 | C11: ДорИнвест | D11: Отдел сварки и сборки Серийных изделий | E11: Сварка полуавтоматическая | F11: Прихватка
A12: 10 | B12: Аппарат сварочный ESAB Warrior Feed 304w зав.№540-841-0038 | C12: ДорИнвест | D12: Отдел сварки и сборки Габаритных изделий | E12: Сварка полуавтоматическая | F12: Прихватка
A13: 11 | B13: Аппарат сварочный LINCOLN ELECTRIC LF 35, СМ-505, зав.№P1111100181, 2015 г.в., инв.№000313377/002058 | C13: ДорИнвест | D13: Отдел сварки и сборки Габаритных изделий | E13: Сварка полуавтоматическая | F13: Прихватка
A14: 12 | B14: Аппарат сварочный ESAB Aristo Mig 5000iw зав.№950-845-0205, 2019 г.в., инв.№000580690 | C14: ДорИнвест | D14: Отдел сварки и сборки Габаритных изделий | E14: Сварка полуавтоматическая | F14: Прихватка
A15: 13 | B15: Аппарат сварочный LINCOLN ELECTRIC СМ-505, СМ-505, зав.№P112010346, 2012 г.в., инв.№000128546 | C15: ДорИнвест | D15: Отдел сварки и сборки Габаритных изделий | E15: Сварка полуавтоматическая | F15: Прихватка
A16: 14 | B16: Аппарат сварочный ESAB Aristo Mig 5000iw зав.№950-626-0114, 2018 г.в., инв.№000551316 | C16: ДорИнвест | D16: Отдел сварки и сборки Габаритных изделий | E16: Сварка полуавтоматическая | F16: Прихватка
A17: 15 | B17: Сварочный позиционер ESSAB 7000 AHMA, зав.№A9268, 2001 г.в., инв.№000150557 | C17: ДорИнвест | D17: Отдел сварки и сборки Габаритных изделий | E17: Сварка полуавтоматическая | F17: Прихватка
A18: 16 | B18: Пост Зачистки: маленький сварочный ESSAB EMP 255ic, зав.№735-836-0014 | C18: ДорИнвест | D18: Отдел сварки и сборки Габаритных изделий | E18: Зачистка
A19: 17 | B19: Станок горизонтально-расточной 2А622Ф4 зав.№351, 1979 г.в., инв.№000001932 | C19: ДорИнвест | D19: Отдел сварки и сборки Габаритных изделий | E19: Расточная
A20: 18 | B20: Аппарат сварочный TransSteel 5000, зав.№20122231, 2018 г.в., инв.№000070173/000130 | C20: ДорИнвест | D20: Отдел сварки и сборки Габаритных изделий | E20: Сварка полуавтоматическая | F20: Прихватка
A21: 19 | B21: Машина газокислородной и плазменной резки MultiTherm 4600, зав. № 286.001.933, 2021 г.в., Германия, инв. № 000743883 | C21: 1 | D21: Отдел заготовка | E21: Газо-плазменная резка | F21: Газо-плазменная резка (стандарт)
A22: 20 | B22: Установка лазерной резки листовых металлов, тип LC Master Direct FO6020-6.0, Россия инв. №001121359 | C22: 1 | D22: Отдел заготовка | E22: Лазерная резка
A23: 21 | B23: Установка лазерной резки листовых металлов, LC Professional-M2, зав. № FO6020-10.0-2053, 2024 г.в. | C23: 1 | D23: Отдел заготовка | E23: Лазерная резка
A24: 22 | B24: Машина газокислородной и плазменной резки MetalMaster 284.001.467 | C24: 1 | D24: Отдел заготовка | E24: Газо-плазменная резка | F24: Газо-плазменная резка (стандарт)
A25: 23 | B25: Машина газоплазменная Кристалл 2,5, 2008 г.в., инв.№000198664 | C25: 1 | D25: Отдел заготовка | E25: Газо-плазменная резка | F25: Газо-плазменная резка (стандарт)
A26: 24 | B26: Станок кромкофрезерный SMB-17C на раме, зав.№PB140510, 2014 г.в., инв.№000352635 | C26: 1 | D26: Отдел заготовка | E26: Слесарная | F26: Фаска (фрезерование)
A27: 25 | B27: Станок кромкофрезерный СН-26 CHALLENGE, зав.№706, 2001 г.в., инв.№000254184 | C27: 1 | D27: Отдел заготовка | E27: Слесарная | F27: Фаска (фрезерование)
A28: 26 | B28: Станок кромкофрезерный XBJ-4 №230409, 2023 г.в., инв.№000958769 | C28: 1 | D28: Отдел заготовка | E28: Слесарная | F28: Фаска (фрезерование)
A29: 27 | B29: Станок кромкорез Wellnit PB-60L зав.№2020082507020-135, инв.№000785390 | C29: 1 | D29: Отдел заготовка | E29: Слесарная | F29: Фаска (фрезерование)
A30: 28 | B30: Станок ленточно-шлифовальный GI150 зав.№2022NKO-001-01-06 инв.№001022328 г.в.2022 | C30: 1 | D30: Отдел заготовка | E30: Слесарная
A31: 29 | B31: Станок ленточно-шлифовальный GIS150 зав.№021231, 2019 г.в., инв.№000625884 | C31: 1 | D31: Отдел заготовка | E31: Слесарная
A32: 30 | B32: Станок ленточно-шлифовальный GI150 зав.№2022NKO-001-01-16 инв.№001022327 г.в.2022 | C32: 1 | D32: Отдел заготовка | E32: Слесарная | F32: Слесарная
A33: 31 | B33: Аппарат сварочный Migatronic КМХ 550 зав.№ 273234 инв.№000024295 | C33: 1 | D33: Отдел заготовка | E33: Прихватка
A34: 32 | B34: Пресс-ножницы IW175 (HKM–175) | C34: 1 | D34: Отдел заготовка | E34: Слесарная
A35: 33 | B35: Станок вертикально-сверлильный 2Н150 зав.№1070, 1973 г.в. | C35: 1 | D35: Отдел заготовка | E35: Сверлильная
A36: 34 | B36: Станок вертикально-сверлильный 2Н150 зав.№6741 | C36: 1 | D36: Отдел заготовка | E36: Сверлильная
A37: 35 | B37: Газовый резак №1 | C37: 1 | D37: Отдел заготовка | E37: Фаска (газо-плазменная резка) | F37: Газо-плазменная резка (ручная)
A38: 36 | B38: Газовый резак №2 | C38: 1 | D38: Отдел заготовка | E38: Фаска (газо-плазменная резка) | F38: Газо-плазменная резка (ручная)
A39: 37 | B39: Газовый резак №3 | C39: 1 | D39: Отдел заготовка | E39: Фаска (газо-плазменная резка) | F39: Газо-плазменная резка (ручная)
A40: 38 | B40: Станок ленточнопильный Н-360НА зав.№15888, 2007 г.в., инв.№000024315 | C40: 1 | D40: Отдел заготовка | E40: Ленточно-отрезная
...

Sheet Операции
A1: 1 | B1: Азотирование | C1: =COUNTIF(Лист1!E$3:G$256, B1) -> 2
A2: 2 | B2: Вальцовка | C2: =COUNTIF(Лист1!E$3:G$256, B2) -> 1
A3: 3 | B3: Внутришлифовальная | C3: =COUNTIF(Лист1!E$3:G$256, B3) -> 5
A4: 4 | B4: Выглаживание | C4: =COUNTIF(Лист1!E$3:G$256, B4) -> 1
A5: 5 | B5: Газо-плазменная резка | C5: =COUNTIF(Лист1!E$3:G$256, B5) -> 3
A6: 6 | B6: Газо-плазменная резка (ручная) | C6: =COUNTIF(Лист1!E$3:G$256, B6) -> 6
A7: 7 | B7: Газо-плазменная резка (стандарт) | C7: =COUNTIF(Лист1!E$3:G$256, B7) -> 3
A8: 8 | B8: Гибка | C8: =COUNTIF(Лист1!E$3:G$256, B8) -> 5
A9: 9 | B9: Долбежная | C9: =COUNTIF(Лист1!E$3:G$256, B9) -> 6
A10: 10 | B10: Закалка ТВЧ | C10: =COUNTIF(Лист1!E$3:G$256, B10) -> 1
A11: 11 | B11: Зачистка | C11: =COUNTIF(Лист1!E$3:G$256, B11) -> 1
A12: 12 | B12: Зубонарезная | C12: =COUNTIF(Лист1!E$3:G$256, B12) -> 6
... A49: 49 | B49: Электроэрозионная | C49: =COUNTIF(Лист1!E$3:G$256, B49) -> 1
